<?xml version="1.0"?>
<robot xmlns:xacro="http://www.ros.org/wiki/xacro">

    <xacro:include filename="inertial_macros.xacro"/>
    <material name="white">
        <color rgba="1 1 1 1" />
    </material>

    <material name="orange">
        <color rgba="1 0.3 0.1 1"/>
    </material>

    <material name="blue">
        <color rgba="0.2 0.2 1 1"/>
    </material>

    <material name="black">
        <color rgba="0 0 0 1"/>
    </material>

    <material name="red">
        <color rgba="1 0 0 1"/>
    </material>


  <!-- BASE_LINK -->
  <link name="base_link">

  </link>
  <!-- BASE_FOOTPRINT LINK -->

  <joint name="base_footprint_joint" type="fixed">
        <parent link="base_link"/>
        <child link="base_footprint"/>
        <origin xyz="0 0 0" rpy="0 0 0"/>
  </joint>

  <link name="base_footprint">
  </link>  

  <joint name="chassis_joint" type="fixed">
        <parent link="base_link"/>
        <child link="chassis"/>
        <origin xyz="0 0 0"/>
  </joint>

 <!-- CHASSIS LINK -->
  <link
    name="chassis">
    <inertial>
      <origin
        xyz="-0.0284708764150052 9.3994676070297E-08 0.0412505139504417"
        rpy="0 0 0" />
      <mass
        value="6" />
      <inertia
        ixx="0.0525609999031616"
        ixy="-1.00992083310068E-07"
        ixz="-5.34892421344281E-07"
        iyy="0.0337926197092529"
        iyz="5.85469145100337E-06"
        izz="0.057635468135065" />
    </inertial>
    <visual>
      <origin
        xyz="0.348 0.182 -0.178 "
        rpy="0  0  -1.5708 " />
      <geometry>
        <mesh
          filename="package://articubot_one/meshes/base_link.STL" />
      </geometry>
      <material
        name="">
        <color
          rgba="0.792156862745098 0.819607843137255 0.933333333333333 1" />
      </material>
    </visual>
    <collision>
      <origin
        xyz="0.348 0.182 -0.178 "
        rpy="0  0  -1.5708 " />
      <geometry>
        <mesh
          filename="package://articubot_one/meshes/base_link.STL" />
      </geometry>
    </collision>
  </link>
  
    <gazebo reference="chassis">
        <material>Gazebo/Orange</material>
    </gazebo>

<!-- LEFT WHEEL LINK -->

  <joint
    name="left_wheel_joint"
    type="continuous">
    <origin
      xyz="-0.10996 0.152 -0.038442"
      rpy="-1.5708 0 0" />
    <parent
      link="chassis" />
    <child
      link="left_wheel" />
    <axis
      xyz="0 0 1" />
    <limit
      effort="10"
      velocity="10" />
  </joint>

  <link
    name="left_wheel">
    <inertial>
      <origin
        xyz="0 0 -0.0054844"
        rpy="0 0 0" />
      <mass
        value="0.18" />
      <inertia
        ixx="4.09222597997732E-05"
        ixy="-7.92355957384699E-21"
        ixz="1.79837729602692E-21"
        iyy="4.09222597997732E-05"
        iyz="-1.24305931164393E-21"
        izz="8.08405617694562E-05" />
    </inertial>
    <visual>
      <origin
        xyz="0 0 0"
        rpy="0 0 0" />
      <geometry>
        <mesh
          filename="package://articubot_one/meshes/left_wheel.STL" />
      </geometry>
      <material
        name="">
        <color
          rgba="0.79216 0.81961 0.93333 1" />
      </material>
    </visual>
    <collision>
      <origin
        xyz="0 0 0"
        rpy="0 0 0" />
      <geometry>
         <sphere radius="0.05"/>
        </geometry>
    </collision>
  </link>
  <gazebo reference="left_wheel">
        <material>Gazebo/Black</material>
    </gazebo>

     <!-- RIGHT WHEEL LINK -->
  <joint
    name="right_wheel_joint"
    type="continuous">
    <origin
      xyz="-0.10996 -0.152 -0.038442"
      rpy="1.5708 0 0" />
    <parent
      link="chassis" />
    <child
      link="right_wheel" />
    <axis
      xyz="0 0 -1" />
    <limit
      effort="10"
      velocity="10" />
  </joint>

  <link
    name="right_wheel">
    <inertial>
      <origin
        xyz="5.5511E-17 -2.7756E-17 -0.0054844"
        rpy="0 0 0" />
      <mass
        value="0.18" />
      <inertia
        ixx="4.09222597997732E-05"
        ixy="-3.18523100866519E-21"
        ixz="-2.20747262208418E-21"
        iyy="4.09222597997732E-05"
        iyz="2.37841378874967E-21"
        izz="8.08405617694561E-05" />
    </inertial>
    <visual>
      <origin
        xyz="0 0 0"
        rpy="0 0 0" />
      <geometry>
        <mesh
          filename="package://articubot_one/meshes/right_wheel.STL" />
      </geometry>
      <material
        name="">
        <color
          rgba="0.79216 0.81961 0.93333 1" />
      </material>
    </visual>
    <collision>
      <origin
        xyz="0 0 0"
        rpy="0 0 0" />
       <geometry>
         <sphere radius="0.05"/>
        </geometry>
    </collision>
  </link>
   <gazebo reference="right_wheel">
        <material>Gazebo/Black</material>
   </gazebo>

   <joint
    name="caster_wheel_left_joint"
    type="fixed">
    <origin
      xyz="0.14224 0.096805 -0.005"
      rpy="0 0 0" />
    <parent
      link="chassis" />
    <child
      link="caster_wheel_left" />
    <axis
      xyz="0 0 0" />
    <limit
      effort="10"
      velocity="10" />
   </joint>
  <link
    name="caster_wheel_left">
    <inertial>
      <origin
        xyz="-2.498E-16 1.6709E-06 -0.029185"
        rpy="0 0 0" />
      <mass
        value="0.084687" />
      <inertia
        ixx="1.70782152480076E-05"
        ixy="8.78401692262484E-22"
        ixz="4.1268418251203E-22"
        iyy="2.46528797191257E-05"
        iyz="6.72965778554763E-22"
        izz="2.7786699731984E-05" />
    </inertial>
    <visual>
      <origin
        xyz="0 0 0"
        rpy="0 0 0" />
      <geometry>
        <mesh
          filename="package://articubot_one/meshes/left_caster.STL" />
      </geometry>
      <material
        name="">
        <color
          rgba="0.79216 0.81961 0.93333 1" />
      </material>
    </visual>
    <collision>
      <origin
        xyz="0 0 0"
        rpy="0 0 0" />
      <geometry>
        <mesh
          filename="package://articubot_one/meshes/left_caster.STL" />
      </geometry>
    </collision>
  </link>

  <joint
    name="caster_wheel_right_joint"
    type="fixed">
    <origin
      xyz="0.14239 -0.092509 -0.005"
      rpy="0 0 0" />
    <parent
      link="chassis" />
    <child
      link="caster_wheel_right" />
    <axis
      xyz="0 0 0" />
    <limit
      effort="10"
      velocity="10" />
  </joint>
  <link
    name="caster_wheel_right">
    <inertial>
      <origin
        xyz="8.3267E-17 1.6709E-06 -0.029185"
        rpy="0 0 0" />
      <mass
        value="0.084687" />
      <inertia
        ixx="1.70782152480077E-05"
        ixy="1.48923077654115E-21"
        ixz="2.59925721632166E-22"
        iyy="2.46528797191257E-05"
        iyz="4.2062569281949E-21"
        izz="2.7786699731984E-05" />
    </inertial>
    <visual>
      <origin
        xyz="0 0 0"
        rpy="0 0 0" />
      <geometry>
        <mesh
          filename="package://articubot_one/meshes/right_caster.STL" />
      </geometry>
      <material
        name="">
        <color
          rgba="0.79216 0.81961 0.93333 1" />
      </material>
    </visual>
    <collision>
      <origin
        xyz="0 0 0"
        rpy="0 0 0" />
      <geometry>
        <mesh
          filename="package://articubot_one/meshes/right_caster.STL" />
      </geometry>
    </collision>
  </link>
   <gazebo reference="caster_wheel_left">
        <material>Gazebo/White</material>
        <mu1 value="0.001"/>
        <mu2 value="0.001"/>
    </gazebo>


    <gazebo reference="caster_wheel_right">
        <material>Gazebo/White</material>
        <mu1 value="0.001"/>
        <mu2 value="0.001"/>
    </gazebo>

</robot>